Traceback (most recent call last):
  File "mi.py", line 106, in main
    driver = mi()
  File "mi.py", line 92, in mi
    driver.find_element_by_xpath(u"(.//*[normalize-space(text()) and normalize-space(.)='\u62fc\u597d\u8fd0'])[1]/preceding::img[3]").click()
  File "/Applications/anaconda3/lib/python3.5/site-packages/selenium/webdriver/remote/webdriver.py", line 387, in find_element_by_xpath
    return self.find_element(by=By.XPATH, value=xpath)
  File "/Applications/anaconda3/lib/python3.5/site-packages/selenium/webdriver/remote/webdriver.py", line 957, in find_element
    'value': value})['value']
  File "/Applications/anaconda3/lib/python3.5/site-packages/selenium/webdriver/remote/webdriver.py", line 314, in execute
    self.error_handler.check_response(response)
  File "/Applications/anaconda3/lib/python3.5/site-packages/selenium/webdriver/remote/errorhandler.py", line 242, in check_response
    raise exception_class(message, screen, stacktrace)
selenium.common.exceptions.NoSuchElementException: Message: no such element: Unable to locate element: {"method":"xpath","selector":"(.//*[normalize-space(text()) and normalize-space(.)='\u62fc\u597d\u8fd0'])[1]/preceding::img[3]"}
  (Session info: chrome=69.0.3497.100)
  (Driver info: chromedriver=2.40.565386 (45a059dc425e08165f9a10324bd1380cc13ca363),platform=Mac OS X 10.13.6 x86_64)


During handling of the above exception, another exception occurred:

Traceback (most recent call last):
  File "mi.py", line 112, in <module>
    main()
  File "mi.py", line 109, in main
    driver.quit()
UnboundLocalError: local variable 'driver' referenced before assignment
Traceback (most recent call last):
  File "/Applications/anaconda3/lib/python3.5/site-packages/selenium/webdriver/common/service.py", line 76, in start
    stdin=PIPE)
  File "/Applications/anaconda3/lib/python3.5/subprocess.py", line 676, in __init__
    restore_signals, start_new_session)
  File "/Applications/anaconda3/lib/python3.5/subprocess.py", line 1289, in _execute_child
    raise child_exception_type(errno_num, err_msg)
FileNotFoundError: [Errno 2] No such file or directory: 'chromedriver'

During handling of the above exception, another exception occurred:

Traceback (most recent call last):
  File "mi.py", line 138, in main
    driver = mi(cookies)
  File "mi.py", line 46, in mi
    driver =webdriver.Chrome()
  File "/Applications/anaconda3/lib/python3.5/site-packages/selenium/webdriver/chrome/webdriver.py", line 68, in __init__
    self.service.start()
  File "/Applications/anaconda3/lib/python3.5/site-packages/selenium/webdriver/common/service.py", line 83, in start
    os.path.basename(self.path), self.start_error_message)
selenium.common.exceptions.WebDriverException: Message: 'chromedriver' executable needs to be in PATH. Please see https://sites.google.com/a/chromium.org/chromedriver/home


During handling of the above exception, another exception occurred:

Traceback (most recent call last):
  File "mi.py", line 144, in <module>
    main()
  File "mi.py", line 141, in main
    driver.quit()
UnboundLocalError: local variable 'driver' referenced before assignment
Traceback (most recent call last):
  File "mi.py", line 82, in mi
    driver.find_element_by_xpath("(.//*[normalize-space(text()) and normalize-space(.)='\ue649'])[1]/following::span[4]").click()
  File "/Applications/anaconda3/lib/python3.5/site-packages/selenium/webdriver/remote/webdriver.py", line 387, in find_element_by_xpath
    return self.find_element(by=By.XPATH, value=xpath)
  File "/Applications/anaconda3/lib/python3.5/site-packages/selenium/webdriver/remote/webdriver.py", line 957, in find_element
    'value': value})['value']
  File "/Applications/anaconda3/lib/python3.5/site-packages/selenium/webdriver/remote/webdriver.py", line 314, in execute
    self.error_handler.check_response(response)
  File "/Applications/anaconda3/lib/python3.5/site-packages/selenium/webdriver/remote/errorhandler.py", line 242, in check_response
    raise exception_class(message, screen, stacktrace)
selenium.common.exceptions.NoSuchElementException: Message: no such element: Unable to locate element: {"method":"xpath","selector":"(.//*[normalize-space(text()) and normalize-space(.)='\ue649'])[1]/following::span[4]"}
  (Session info: chrome=69.0.3497.100)
  (Driver info: chromedriver=2.42.591059 (a3d9684d10d61aa0c45f6723b327283be1ebaad8),platform=Mac OS X 10.14.0 x86_64)


During handling of the above exception, another exception occurred:

Traceback (most recent call last):
  File "mi.py", line 136, in main
    driver = mi(cookies)
  File "mi.py", line 84, in mi
    driver.find_element_by_xpath(u"(.//*[normalize-space(text()) and normalize-space(.)='\u4e00\u5206\u94b1\u62fc\u597d\u8fd0\u4f18\u60e0\u5238'])[1]/following::button[1]").click()
  File "/Applications/anaconda3/lib/python3.5/site-packages/selenium/webdriver/remote/webelement.py", line 80, in click
    self._execute(Command.CLICK_ELEMENT)
  File "/Applications/anaconda3/lib/python3.5/site-packages/selenium/webdriver/remote/webelement.py", line 628, in _execute
    return self._parent.execute(command, params)
  File "/Applications/anaconda3/lib/python3.5/site-packages/selenium/webdriver/remote/webdriver.py", line 314, in execute
    self.error_handler.check_response(response)
  File "/Applications/anaconda3/lib/python3.5/site-packages/selenium/webdriver/remote/errorhandler.py", line 242, in check_response
    raise exception_class(message, screen, stacktrace)
selenium.common.exceptions.WebDriverException: Message: unknown error: Element is not clickable at point (199, 936)
  (Session info: chrome=69.0.3497.100)
  (Driver info: chromedriver=2.42.591059 (a3d9684d10d61aa0c45f6723b327283be1ebaad8),platform=Mac OS X 10.14.0 x86_64)


During handling of the above exception, another exception occurred:

Traceback (most recent call last):
  File "mi.py", line 142, in <module>
    main()
  File "mi.py", line 139, in main
    driver.quit()
UnboundLocalError: local variable 'driver' referenced before assignment
